<?xml version="1.0" ?>
<robot name="box">
  <link name="base_link">
    <inertial>
      <origin rpy="0 0 0" xyz="0 0 0"/>
      <mass value="0"/>
      <inertia ixx="1.0" ixy="0.0" ixz="0.0" iyy="1.0" iyz="0.0" izz="1.0"/>
    </inertial>
    <visual>
      <origin rpy="0 0 0" xyz="0 0 0"/>
      <geometry>
        <mesh filename="box-T2F_N3F_V3F.obj" scale="1 1 1"/>
      </geometry>
      <material name="white">
        <color rgba="1 1 1 1"/>
      </material>
    </visual>
    <collision>
      <origin rpy="0 0 0" xyz="0 0 0"/>
      <geometry>
        <mesh filename="box-T2F_N3F_V3F.obj" scale="1 1 1"/>
      </geometry>
    </collision>
  </link>
  <link name="right_leg">
    <inertial>
      <origin rpy="0 0 0" xyz="2 0 0"/>
      <mass value="10"/>
      <inertia ixx="1.0" ixy="0.0" ixz="0.0" iyy="1.0" iyz="0.0" izz="1.0"/>
    </inertial>
    <visual>
      <origin rpy="0 0 0" xyz="2 0 0"/>
      <geometry>
        <mesh filename="box-T2F_N3F_V3F.obj" scale="1 1 1"/>
      </geometry>
      <material name="white">
        <color rgba="1 1 1 1"/>
      </material>
    </visual>
    <collision>
      <origin rpy="0 0 0" xyz="2 0 0"/>
      <geometry>
        <mesh filename="box-T2F_N3F_V3F.obj" scale="1 1 1"/>
      </geometry>
    </collision>
  </link>
  <joint name="base_to_right_leg" type="revolute">
    <axis xyz="0 1 0"/>
    <limit effort="1000.0" lower="-1.57" upper="1.57" velocity="0.5"/>
    <origin rpy="0 0 0" xyz="1 0 0"/>
    <parent link="base_link"/>
    <child link="right_leg"/>
  </joint>
</robot>